Workbook
Name Analysis_Period: 'Property Summary'!$C$8
Name Analysis_Start: 'Property Summary'!$C$7
Name Basis: 'Property Summary'!$F$6
Name Debt: 'Property Summary'!$F$18
Name Discount_Rate: 'Property Summary'!$C$12
Name Effective_Hold_Period: 'Property Summary'!$C$15
Name Equity_Share_LPs: 'Investor Returns'!$C$9
Name Equity_Share_Sponsor: 'Investor Returns'!$C$8
Name GP_Only_No_LPs: 'Investor Returns'!$E$8
Name Initial_Equity: 'Property Summary'!$F$23
Name Preferred_Return: 'Investor Returns'!$E$14
Name Promote_Method: 'Investor Returns'!$D$4
Name Property_Name: 'Property Summary'!$C$3
Name Purchase_Price: 'Property Summary'!$C$18
Name Terminal_Cap_Year: 'Property Summary'!$C$9
Name Total_Equity: 'Investor Returns'!$D$10
Name Units: 'Property Summary'!$F$3

Sheet Property Summary
B2: Property Summary
B3: Property Name | C3: XYZ Condos | E3: Number of Units | F3: 80 | H3: Capitalization | I3: % | J3: Amount
B4: City, State/Region | C4: Grand Cayman, CI | E4: Upfront CapEx | F4: 30000 | H4: GP/Sponsor | I4: =Equity_Share_Sponsor -> 0.1 | J4: ='Investor Returns'!D8 -> 1966879.2
B5: Current Occupancy | C5: 0.89 | E5: Acquisition Cost | F5: 0.01 | H5: LP Investors | I5: =1-I4 -> 0.9 | J5: ='Investor Returns'!D9 -> 17701913
B6: Purchase Price Method | C6: Cap Year 1 NOI | E6: All-in-Basis | F6: =((1+F5)*Purchase_Price)+(Debt*F30)+F4 -> 35928792 | H6: [See Investor Returns Tab To Configure]
B7: Analysis Start Date | C7: 43842 | E7: Going-In Cap Rate | F7: =$F$9/Purchase_Price -> 0.065
B8: Analysis Period (Years) | C8: 15 | E8: Price/Unit | F8: =Purchase_Price/Units -> 442278.36
B9: Terminal Cap Year | C9: =MIN(Analysis_Period+1,15) -> 15 | E9: Y1 NOI | F9: ='Property Returns'!$D$8 -> 2299847.5
B10: Terminal Cap Rate Growth/Yr | C10: 5 | E10: Y3 NOI | F10: ='Property Returns'!$F$8 -> 2407303.2
B11: Market Cap Rate (Y1) | C11: 0.065 | E11: ="Terminal Cap Rate (Yr "&Terminal_Cap_Year&")" -> Terminal Cap Rate (Yr 15) | F11: =$F$7+(Effective_Hold_Period*($C$10/10000)) -> 0.0725
B12: Discount Rate | C12: 0.05 | E12: Terminal Value | F12: =HLOOKUP(Effective_Hold_Period,'Property Returns'!$D$4:$R$42,10,FALSE) -> 37781965
B13: Replacement Cost (per unit) | C13: 210000
B14: Set Purchase Price | C14: 5000000 | E14: Other Income/Year | F14: 25000
B15: Effective Hold Period | C15: =MIN(Analysis_Period,Terminal_Cap_Year) -> 15 | E15: General Vacancy | F15: 0.13
B17: Property Metrics | E17: Financing Assumptions | H17: Inflation
B18: Purchase Price | C18: =IF($C$6="Manual Input", $C$14, IF($C$6="Present Value", $C$19, IF($C$6="Cap Year 1 NOI", $F$9/$C$11,$C$20))) -> 35382269 | E18: Loan Amount | F18: 16270000 | H18: Rent | I18: 0.015
B19: ="Present Value @ "&TEXT($C$12,"0.00%") -> Present Value @ 5.00% | C19: =NPV(Discount_Rate,'Property Returns'!$D$19:$R$19) -> 42321157 | E19: Value Basis for LTV | F19: Purchase Price | H19: Other Income | I19: 0.01
B20: ="Replacement Cost @ "&$C$13/1000&"k/unit" -> Replacement Cost @ 210k/unit | C20: =$C$13*Units -> 16800000 | E20: ="LTV ("&F19&")" -> LTV (Purchase Price) | F20: =IF($F$19="Purchase Price", Debt/Purchase_Price, IF($F$19="DCF Value", Debt/C19, Debt/F12)) -> 0.45983484 | H20: Operating Expenses | I20: 0.03
E21: LTC | F21: =Debt/Basis -> 0.45284017 | H21: Capital Expenditure | I21: 0.025
B22: Unlevered IRR | C22: =HLOOKUP(Effective_Hold_Period,'Property Returns'!$D$4:$S$42,18,FALSE) -> 0.066536708 | E22: Lender Fees ($) | F22: =Debt*$F$30 -> 162700 | H22: Releasing Costs | I22: 0.02
B23: Unlevered Equity Multiple (EM) | C23: =HLOOKUP(Effective_Hold_Period,'Property Returns'!$D$4:$S$42,19,FALSE) -> 2.0375574 | E23: Initial Equity Required | F23: =Basis-Debt -> 19658792
B24: Avg. Free and Clear Return | C24: =HLOOKUP(Effective_Hold_Period,'Property Returns'!$D$4:$S$42,15,FALSE) -> 0.065731889 | E24: Total Equity Required | F24: =Total_Equity -> 19668792
B26: Levered IRR | C26: =HLOOKUP(Effective_Hold_Period,'Property Returns'!$D$4:$S$42,36,FALSE) -> 0.90252903 | E26: Interest Rate | F26: 0.0725 | H26: Unit of Area | I26: SQFT
B27: Levered EM | C27: =HLOOKUP(Effective_Hold_Period,'Property Returns'!$D$4:$S$42,37,FALSE) -> 13.610558 | E27: Years I/O | F27: 0 | H27: Net Rentable Area (NRA) | I27: =SUMPRODUCT('Rent Roll'!C5:C10,'Rent Roll'!F5:F10) -> 62520
B28: Avg. Cash-on-Cash Return | C28: =HLOOKUP(Effective_Hold_Period,'Property Returns'!$D$4:$S$42,34,FALSE) -> 0.052382995 | E28: Amortization Period | F28: 30
E29: Term | F29: 10
B30: Min. DSCR (NOI) | C30: =MIN('Property Returns'!D28:R28) -> 1.7267665 | E30: Lender Fees (%) | F30: 0.01
B31: Min. Debt Yield (NOI) | C31: =MIN('Property Returns'!D29:R29) -> 0.12697548
B33: Investor Returns | C33: GP/Sponsor | E33: Limited Partner(s)
B34: IRR | C34: ='Investor Returns'!D43 -> 0.091151742 | E34: ='Investor Returns'!D29 -> 0.04584265
B35: Total Distributions | C35: ='Investor Returns'!D38 -> 5350982.4 | E35: ='Investor Returns'!D25 -> 29907409
B36: Total Contributions | C36: ='Investor Returns'!D40 -> 1966879.2 | E36: ='Investor Returns'!D26 -> 17701913
B37: Total Profit | C37: ='Investor Returns'!D41 -> 3704103.2 | E37: ='Investor Returns'!D27 -> 12205497
B38: Equity Multiple | C38: ='Investor Returns'!D44 -> 2.8928625 | E38: ='Investor Returns'!D30 -> 1.6895016

Sheet Rent Roll
B2: Property Unit Mix | G2: Total Units: | H2: =Units -> 80 | J2: Units Remaining: | K2: =H2-SUM(C5:C10) -> 0
P3: Blended
B4: Unit Type | C4: # of Units | D4: Beds | E4: Baths | F4: ="Rentable Area ("&'Property Summary'!$I$26&")" -> Rentable Area (SQFT) | G4: In-Place Rent/Mo. | H4: Market Rent/Mo. | I4: Month to Roll to Market | J4: Lease Term | K4: CapEx/Unit/Mo. | L4: Free Rent per Lease | M4: Days Vacant Between Leases | N4: Releasing Cost per Unit | O4: Probability of Renewal | P4: Free Rent | Q4: Days Vacant | R4: Releasing Cost
B5: Studio | C5: 22 | D5: 0 | E5: 1 | F5: 470 | G5: 2200 | H5: 2350 | I5: 13 | J5: 12 | K5: 70 | L5: 0 | M5: 25 | N5: 400 | O5: 0.6 | P5: =IF($B5<>"", (1-$O5)*$L5, "") -> 0 | Q5: =IF($B5<>"", (1-$O5)*$M5, "") -> 10 | R5: =IF($B5<>"", (1-$O5)*$N5, "") -> 160
B6: 1bd/1ba | C6: 24 | D6: 1 | E6: 1 | F6: 630 | G6: 2340 | H6: 2500 | I6: 16 | J6: 12 | K6: 75 | L6: 0 | M6: 25 | N6: 400 | O6: 0.6 | P6: =IF($B6<>"", (1-$O6)*$L6, "") -> 0 | Q6: =IF($B6<>"", (1-$O6)*$M6, "") -> 10 | R6: =IF($B6<>"", (1-$O6)*$N6, "") -> 160
B7: 2bd/2ba | C7: 20 | D7: 2 | E7: 2 | F7: 955 | G7: 4800 | H7: 4950 | I7: 19 | J7: 12 | K7: 120 | L7: 0 | M7: 28 | N7: 550 | O7: 0.6 | P7: =IF($B7<>"", (1-$O7)*$L7, "") -> 0 | Q7: =IF($B7<>"", (1-$O7)*$M7, "") -> 11.2 | R7: =IF($B7<>"", (1-$O7)*$N7, "") -> 220
B8: 3bd/3ba | C8: 8 | D8: 3 | E8: 3 | F8: 1120 | G8: 5400 | H8: 5500 | I8: 14 | J8: 12 | K8: 160 | L8: 0 | M8: 32 | N8: 600 | O8: 0.6 | P8: =IF($B8<>"", (1-$O8)*$L8, "") -> 0 | Q8: =IF($B8<>"", (1-$O8)*$M8, "") -> 12.8 | R8: =IF($B8<>"", (1-$O8)*$N8, "") -> 240
B9: 4bd/4ba | C9: 6 | D9: 4 | E9: 4 | F9: 1500 | G9: 5900 | H9: 6150 | I9: 20 | J9: 12 | K9: 180 | L9: 0 | M9: 38 | N9: 800 | O9: 0.6 | P9: =IF($B9<>"", (1-$O9)*$L9, "") -> 0 | Q9: =IF($B9<>"", (1-$O9)*$M9, "") -> 15.2 | R9: =IF($B9<>"", (1-$O9)*$N9, "") -> 320
P10: =IF($B10<>"", (1-$O10)*$L10, "") | Q10: =IF($B10<>"", (1-$O10)*$M10, "") | R10: =IF($B10<>"", (1-$O10)*$N10, "")

Sheet Expenses
B2: Operating Expenses Assumptions
B5: Growth Rate | D5: Year 1 Per Unit | E5: ='Property Returns'!D4 -> 1 | F5: ='Property Returns'!E4 -> 2 | G5: ='Property Returns'!F4 -> 3 | H5: ='Property Returns'!G4 -> 4 | I5: ='Property Returns'!H4 -> 5 | J5: ='Property Returns'!I4 -> 6 | K5: ='Property Returns'!J4 -> 7 | L5: ='Property Returns'!K4 -> 8 | ... S5: ='Property Returns'!R4 -> 15
B6: ='Property Summary'!$I$20 -> 0.03 | C6: -Marketing | D6: =E6/Units -> -300 | E6: -24000 | F6: =IF(OR(F$5="",F$5=0),"",-ABS((E6*(1+$B6)))) -> -24720 | G6: =IF(OR(G$5="",G$5=0),"",-ABS((F6*(1+$B6)))) -> -25461.6 | H6: =IF(OR(H$5="",H$5=0),"",-ABS((G6*(1+$B6)))) -> -26225.448 | I6: =IF(OR(I$5="",I$5=0),"",-ABS((H6*(1+$B6)))) -> -27012.211 | J6: =IF(OR(J$5="",J$5=0),"",-ABS((I6*(1+$B6)))) -> -27822.578 | K6: =IF(OR(K$5="",K$5=0),"",-ABS((J6*(1+$B6)))) -> -28657.255 | L6: =IF(OR(L$5="",L$5=0),"",-ABS((K6*(1+$B6)))) -> -29516.973 | M6: =IF(OR(M$5="",M$5=0),"",-ABS((L6*(1+$B6)))) -> -30402.482 | ... S6: =IF(OR(S$5="",S$5=0),"",-ABS((R6*(1+$B6)))) -> -36302.153
B7: ='Property Summary'!$I$20 -> 0.03 | C7: -Administrative | D7: =E7/Units -> -412.5 | E7: -33000 | F7: =IF(OR(F$5="",F$5=0),"",-ABS((E7*(1+$B7)))) -> -33990 | G7: =IF(OR(G$5="",G$5=0),"",-ABS((F7*(1+$B7)))) -> -35009.7 | H7: =IF(OR(H$5="",H$5=0),"",-ABS((G7*(1+$B7)))) -> -36059.991 | I7: =IF(OR(I$5="",I$5=0),"",-ABS((H7*(1+$B7)))) -> -37141.791 | J7: =IF(OR(J$5="",J$5=0),"",-ABS((I7*(1+$B7)))) -> -38256.044 | K7: =IF(OR(K$5="",K$5=0),"",-ABS((J7*(1+$B7)))) -> -39403.726 | L7: =IF(OR(L$5="",L$5=0),"",-ABS((K7*(1+$B7)))) -> -40585.838 | M7: =IF(OR(M$5="",M$5=0),"",-ABS((L7*(1+$B7)))) -> -41803.413 | ... S7: =IF(OR(S$5="",S$5=0),"",-ABS((R7*(1+$B7)))) -> -49915.461
B8: ='Property Summary'!$I$20 -> 0.03 | C8: -Utilities | D8: =E8/Units -> -1237.5 | E8: -99000 | F8: =IF(OR(F$5="",F$5=0),"",-ABS((E8*(1+$B8)))) -> -101970 | G8: =IF(OR(G$5="",G$5=0),"",-ABS((F8*(1+$B8)))) -> -105029.1 | H8: =IF(OR(H$5="",H$5=0),"",-ABS((G8*(1+$B8)))) -> -108179.97 | I8: =IF(OR(I$5="",I$5=0),"",-ABS((H8*(1+$B8)))) -> -111425.37 | J8: =IF(OR(J$5="",J$5=0),"",-ABS((I8*(1+$B8)))) -> -114768.13 | K8: =IF(OR(K$5="",K$5=0),"",-ABS((J8*(1+$B8)))) -> -118211.18 | L8: =IF(OR(L$5="",L$5=0),"",-ABS((K8*(1+$B8)))) -> -121757.51 | M8: =IF(OR(M$5="",M$5=0),"",-ABS((L8*(1+$B8)))) -> -125410.24 | ... S8: =IF(OR(S$5="",S$5=0),"",-ABS((R8*(1+$B8)))) -> -149746.38
B9: ='Property Summary'!$I$20 -> 0.03 | C9: -Payroll | D9: =E9/Units -> -1900 | E9: -152000 | F9: =IF(OR(F$5="",F$5=0),"",-ABS((E9*(1+$B9)))) -> -156560 | G9: =IF(OR(G$5="",G$5=0),"",-ABS((F9*(1+$B9)))) -> -161256.8 | H9: =IF(OR(H$5="",H$5=0),"",-ABS((G9*(1+$B9)))) -> -166094.5 | I9: =IF(OR(I$5="",I$5=0),"",-ABS((H9*(1+$B9)))) -> -171077.34 | J9: =IF(OR(J$5="",J$5=0),"",-ABS((I9*(1+$B9)))) -> -176209.66 | K9: =IF(OR(K$5="",K$5=0),"",-ABS((J9*(1+$B9)))) -> -181495.95 | L9: =IF(OR(L$5="",L$5=0),"",-ABS((K9*(1+$B9)))) -> -186940.83 | M9: =IF(OR(M$5="",M$5=0),"",-ABS((L9*(1+$B9)))) -> -192549.05 | ... S9: =IF(OR(S$5="",S$5=0),"",-ABS((R9*(1+$B9)))) -> -229913.64
B10: ='Property Summary'!$I$20 -> 0.03 | C10: -Repair and Maintenance | D10: =E10/Units -> -1055 | E10: -84400 | F10: =IF(OR(F$5="",F$5=0),"",-ABS((E10*(1+$B10)))) -> -86932 | G10: =IF(OR(G$5="",G$5=0),"",-ABS((F10*(1+$B10)))) -> -89539.96 | H10: =IF(OR(H$5="",H$5=0),"",-ABS((G10*(1+$B10)))) -> -92226.159 | I10: =IF(OR(I$5="",I$5=0),"",-ABS((H10*(1+$B10)))) -> -94992.944 | J10: =IF(OR(J$5="",J$5=0),"",-ABS((I10*(1+$B10)))) -> -97842.732 | K10: =IF(OR(K$5="",K$5=0),"",-ABS((J10*(1+$B10)))) -> -100778.01 | L10: =IF(OR(L$5="",L$5=0),"",-ABS((K10*(1+$B10)))) -> -103801.35 | M10: =IF(OR(M$5="",M$5=0),"",-ABS((L10*(1+$B10)))) -> -106915.39 | ... S10: =IF(OR(S$5="",S$5=0),"",-ABS((R10*(1+$B10)))) -> -127662.57
B11: 0.03 | C11: -Management (as % of EGR) | D11: =E11/Units -> -1102.2864 | E11: =IF(OR(E$5="",E$5=0),"",(-$B11*'Annual Cash Flow'!E11)) -> -88182.912 | F11: =IF(OR(F$5="",F$5=0),"",-ABS((E11*(1+$B11)))) -> -90828.399 | G11: =IF(OR(G$5="",G$5=0),"",-ABS((F11*(1+$B11)))) -> -93553.251 | H11: =IF(OR(H$5="",H$5=0),"",-ABS((G11*(1+$B11)))) -> -96359.849 | I11: =IF(OR(I$5="",I$5=0),"",-ABS((H11*(1+$B11)))) -> -99250.644 | J11: =IF(OR(J$5="",J$5=0),"",-ABS((I11*(1+$B11)))) -> -102228.16 | K11: =IF(OR(K$5="",K$5=0),"",-ABS((J11*(1+$B11)))) -> -105295.01 | L11: =IF(OR(L$5="",L$5=0),"",-ABS((K11*(1+$B11)))) -> -108453.86 | M11: =IF(OR(M$5="",M$5=0),"",-ABS((L11*(1+$B11)))) -> -111707.47 | ... S11: =IF(OR(S$5="",S$5=0),"",-ABS((R11*(1+$B11)))) -> -133384.57
B12: ='Property Summary'!$I$20 -> 0.03 | C12: -Insurance | D12: =E12/Units -> -487.5 | E12: -39000 | F12: =IF(OR(F$5="",F$5=0),"",-ABS((E12*(1+$B12)))) -> -40170 | G12: =IF(OR(G$5="",G$5=0),"",-ABS((F12*(1+$B12)))) -> -41375.1 | H12: =IF(OR(H$5="",H$5=0),"",-ABS((G12*(1+$B12)))) -> -42616.353 | I12: =IF(OR(I$5="",I$5=0),"",-ABS((H12*(1+$B12)))) -> -43894.844 | J12: =IF(OR(J$5="",J$5=0),"",-ABS((I12*(1+$B12)))) -> -45211.689 | K12: =IF(OR(K$5="",K$5=0),"",-ABS((J12*(1+$B12)))) -> -46568.04 | L12: =IF(OR(L$5="",L$5=0),"",-ABS((K12*(1+$B12)))) -> -47965.081 | M12: =IF(OR(M$5="",M$5=0),"",-ABS((L12*(1+$B12)))) -> -49404.033 | ... S12: =IF(OR(S$5="",S$5=0),"",-ABS((R12*(1+$B12)))) -> -58990.999
B13: ='Property Summary'!$I$20 -> 0.03 | C13: -Taxes | D13: =E13/Units -> -1500 | E13: -120000 | F13: =IF(OR(F$5="",F$5=0),"",-ABS((E13*(1+$B13)))) -> -123600 | G13: =IF(OR(G$5="",G$5=0),"",-ABS((F13*(1+$B13)))) -> -127308 | H13: =IF(OR(H$5="",H$5=0),"",-ABS((G13*(1+$B13)))) -> -131127.24 | I13: =IF(OR(I$5="",I$5=0),"",-ABS((H13*(1+$B13)))) -> -135061.06 | J13: =IF(OR(J$5="",J$5=0),"",-ABS((I13*(1+$B13)))) -> -139112.89 | K13: =IF(OR(K$5="",K$5=0),"",-ABS((J13*(1+$B13)))) -> -143286.28 | L13: =IF(OR(L$5="",L$5=0),"",-ABS((K13*(1+$B13)))) -> -147584.86 | M13: =IF(OR(M$5="",M$5=0),"",-ABS((L13*(1+$B13)))) -> -152012.41 | ... S13: =IF(OR(S$5="",S$5=0),"",-ABS((R13*(1+$B13)))) -> -181510.77
B14: ='Property Summary'!$I$20 -> 0.03 | C14: Operating Expenses | D14: =E14/Units -> -7994.7864 | E14: {=IF(OR(E5="",E5=0),"",-SUM(ABS(E6:E13)))} -> -639582.91 | F14: =IF(OR(F$5="",F$5=0),"",-ABS((E14*(1+$B14)))) -> -658770.4 | G14: =IF(OR(G$5="",G$5=0),"",-ABS((F14*(1+$B14)))) -> -678533.51 | H14: =IF(OR(H$5="",H$5=0),"",-ABS((G14*(1+$B14)))) -> -698889.52 | I14: =IF(OR(I$5="",I$5=0),"",-ABS((H14*(1+$B14)))) -> -719856.2 | J14: =IF(OR(J$5="",J$5=0),"",-ABS((I14*(1+$B14)))) -> -741451.89 | K14: =IF(OR(K$5="",K$5=0),"",-ABS((J14*(1+$B14)))) -> -763695.44 | L14: =IF(OR(L$5="",L$5=0),"",-ABS((K14*(1+$B14)))) -> -786606.31 | M14: =IF(OR(M$5="",M$5=0),"",-ABS((L14*(1+$B14)))) -> -810204.5 | ... S14: =IF(OR(S$5="",S$5=0),"",-ABS((R14*(1+$B14)))) -> -967426.54
D18: Year | E18: =E5 -> 1 | F18: =F5 -> 2 | G18: =G5 -> 3 | H18: =H5 -> 4 | I18: =I5 -> 5 | J18: =J5 -> 6 | K18: =K5 -> 7 | L18: =L5 -> 8 | ... S18: =S5 -> 15
B19: Property Renovation/Improvement Costs | E19: 350000 | F19: 200000 | G19: 0 | H19: 0 | I19: 0 | J19: 0 | K19: 0 | L19: 0 | M19: 0 | N19: 0 | O19: 0 | P19: 0 | Q19: 0 | R19: 0 | S19: 0
B20: Total | E20: =IF(OR(E18="",E18=0),"",-ABS(E19)) -> -350000 | F20: =IF(OR(F18="",F18=0),"",-ABS(F19)) -> -200000 | G20: =IF(OR(G18="",G18=0),"",-ABS(G19)) -> 0 | H20: =IF(OR(H18="",H18=0),"",-ABS(H19)) -> 0 | I20: =IF(OR(I18="",I18=0),"",-ABS(I19)) -> 0 | J20: =IF(OR(J18="",J18=0),"",-ABS(J19)) -> 0 | K20: =IF(OR(K18="",K18=0),"",-ABS(K19)) -> 0 | L20: =IF(OR(L18="",L18=0),"",-ABS(L19)) -> 0 | ... S20: =IF(OR(S18="",S18=0),"",-ABS(S19)) -> 0

Sheet Annual Cash Flow
B2: Annual Cash Flow
D4: Ratios | E4: ='Property Returns'!D4 -> 1 | F4: ='Property Returns'!E4 -> 2 | G4: ='Property Returns'!F4 -> 3 | H4: ='Property Returns'!G4 -> 4 | I4: ='Property Returns'!H4 -> 5 | J4: ='Property Returns'!I4 -> 6 | K4: ='Property Returns'!J4 -> 7 | L4: ='Property Returns'!K4 -> 8 | ... S4: ='Property Returns'!R4 -> 15
B5: + Base Rent | E5: =IF(OR(E$4="",E$4=0),"",SUMIF(Calculations!C$13:FZ$13,E4,Calculations!C$22:FZ$22)) -> 3349920 | F5: =IF(OR(F$4="",F$4=0),"",SUMIF(Calculations!D$13:GA$13,F4,Calculations!D$22:GA$22)) -> 3510255.7 | G5: =IF(OR(G$4="",G$4=0),"",SUMIF(Calculations!E$13:GB$13,G4,Calculations!E$22:GB$22)) -> 3604963.3 | H5: =IF(OR(H$4="",H$4=0),"",SUMIF(Calculations!F$13:GC$13,H4,Calculations!F$22:GC$22)) -> 3659037.8 | I5: =IF(OR(I$4="",I$4=0),"",SUMIF(Calculations!G$13:GD$13,I4,Calculations!G$22:GD$22)) -> 3713923.3 | J5: =IF(OR(J$4="",J$4=0),"",SUMIF(Calculations!H$13:GE$13,J4,Calculations!H$22:GE$22)) -> 3769632.2 | K5: =IF(OR(K$4="",K$4=0),"",SUMIF(Calculations!I$13:GF$13,K4,Calculations!I$22:GF$22)) -> 3826176.7 | L5: =IF(OR(L$4="",L$4=0),"",SUMIF(Calculations!J$13:GG$13,L4,Calculations!J$22:GG$22)) -> 3883569.3 | ... S5: =IF(OR(S$4="",S$4=0),"",SUMIF(Calculations!Q$13:GN$13,S4,Calculations!Q$22:GN$22)) -> 4310159.7
B6: + Other Income | D6: =AVERAGE(E6:P6)/AVERAGE(E7:P7) -> 0.0069287912 | E6: =IF(OR(E$4="",E$4=0),"",'Property Summary'!$F$14*(1+'Property Summary'!$I$19)^(E4-1)) -> 25000 | F6: =IF(OR(F$4="",F$4=0),"",'Property Summary'!$F$14*(1+'Property Summary'!$I$19)^(F4-1)) -> 25250 | G6: =IF(OR(G$4="",G$4=0),"",'Property Summary'!$F$14*(1+'Property Summary'!$I$19)^(G4-1)) -> 25502.5 | H6: =IF(OR(H$4="",H$4=0),"",'Property Summary'!$F$14*(1+'Property Summary'!$I$19)^(H4-1)) -> 25757.525 | I6: =IF(OR(I$4="",I$4=0),"",'Property Summary'!$F$14*(1+'Property Summary'!$I$19)^(I4-1)) -> 26015.1 | J6: =IF(OR(J$4="",J$4=0),"",'Property Summary'!$F$14*(1+'Property Summary'!$I$19)^(J4-1)) -> 26275.251 | K6: =IF(OR(K$4="",K$4=0),"",'Property Summary'!$F$14*(1+'Property Summary'!$I$19)^(K4-1)) -> 26538.004 | L6: =IF(OR(L$4="",L$4=0),"",'Property Summary'!$F$14*(1+'Property Summary'!$I$19)^(L4-1)) -> 26803.384 | ... S6: =IF(OR(S$4="",S$4=0),"",'Property Summary'!$F$14*(1+'Property Summary'!$I$19)^(S4-1)) -> 28736.855
B7: Gross Potential Income | E7: =IF(OR(E$4="",E$4=0),"",SUM(E5:E6)) -> 3374920 | F7: =IF(OR(F$4="",F$4=0),"",SUM(F5:F6)) -> 3535505.7 | G7: =IF(OR(G$4="",G$4=0),"",SUM(G5:G6)) -> 3630465.8 | H7: =IF(OR(H$4="",H$4=0),"",SUM(H5:H6)) -> 3684795.3 | I7: =IF(OR(I$4="",I$4=0),"",SUM(I5:I6)) -> 3739938.4 | J7: =IF(OR(J$4="",J$4=0),"",SUM(J5:J6)) -> 3795907.4 | K7: =IF(OR(K$4="",K$4=0),"",SUM(K5:K6)) -> 3852714.7 | L7: =IF(OR(L$4="",L$4=0),"",SUM(L5:L6)) -> 3910372.7 | ... S7: =IF(OR(S$4="",S$4=0),"",SUM(S5:S6)) -> 4338896.5
B9: - Rent Abatement | D9: =AVERAGE(E9:P9)/AVERAGE($E$7:$P$7) -> 0 | E9: =IF(OR(E$4="",E$4=0),"",-SUMIF(Calculations!$C$49:$FZ$49,E$4,Calculations!$C$58:$FZ$58)) -> 0 | F9: =IF(OR(F$4="",F$4=0),"",-SUMIF(Calculations!$C$49:$FZ$49,F$4,Calculations!$C$58:$FZ$58)) -> 0 | G9: =IF(OR(G$4="",G$4=0),"",-SUMIF(Calculations!$C$49:$FZ$49,G$4,Calculations!$C$58:$FZ$58)) -> 0 | H9: =IF(OR(H$4="",H$4=0),"",-SUMIF(Calculations!$C$49:$FZ$49,H$4,Calculations!$C$58:$FZ$58)) -> 0 | I9: =IF(OR(I$4="",I$4=0),"",-SUMIF(Calculations!$C$49:$FZ$49,I$4,Calculations!$C$58:$FZ$58)) -> 0 | J9: =IF(OR(J$4="",J$4=0),"",-SUMIF(Calculations!$C$49:$FZ$49,J$4,Calculations!$C$58:$FZ$58)) -> 0 | K9: =IF(OR(K$4="",K$4=0),"",-SUMIF(Calculations!$C$49:$FZ$49,K$4,Calculations!$C$58:$FZ$58)) -> 0 | L9: =IF(OR(L$4="",L$4=0),"",-SUMIF(Calculations!$C$49:$FZ$49,L$4,Calculations!$C$58:$FZ$58)) -> 0 | ... S9: =IF(OR(S$4="",S$4=0),"",-SUMIF(Calculations!$C$49:$FZ$49,S$4,Calculations!$C$58:$FZ$58)) -> 0
B10: - Vacancy | D10: =-AVERAGE(E10:P10)/AVERAGE($E$7:$P$7) -> 0.14845557 | E10: =IF(OR(E$4="",E$4=0),"",-SUMIF(Calculations!$C$61:$FZ$61,E$4,Calculations!$C$70:$FZ$70)) -> -435489.6 | F10: =IF(OR(F$4="",F$4=0),"",-SUMIF(Calculations!$C$61:$FZ$61,F$4,Calculations!$C$70:$FZ$70)) -> -528846.4 | G10: =IF(OR(G$4="",G$4=0),"",-SUMIF(Calculations!$C$61:$FZ$61,G$4,Calculations!$C$70:$FZ$70)) -> -544629.13 | H10: =IF(OR(H$4="",H$4=0),"",-SUMIF(Calculations!$C$61:$FZ$61,H$4,Calculations!$C$70:$FZ$70)) -> -552798.57 | I10: =IF(OR(I$4="",I$4=0),"",-SUMIF(Calculations!$C$61:$FZ$61,I$4,Calculations!$C$70:$FZ$70)) -> -561090.55 | J10: =IF(OR(J$4="",J$4=0),"",-SUMIF(Calculations!$C$61:$FZ$61,J$4,Calculations!$C$70:$FZ$70)) -> -569506.91 | K10: =IF(OR(K$4="",K$4=0),"",-SUMIF(Calculations!$C$61:$FZ$61,K$4,Calculations!$C$70:$FZ$70)) -> -578049.51 | L10: =IF(OR(L$4="",L$4=0),"",-SUMIF(Calculations!$C$61:$FZ$61,L$4,Calculations!$C$70:$FZ$70)) -> -586720.25 | ... S10: =IF(OR(S$4="",S$4=0),"",-SUMIF(Calculations!$C$61:$FZ$61,S$4,Calculations!$C$70:$FZ$70)) -> -651168.49
B11: Effective Gross Revenue | D11: =AVERAGE(E11:P11)/AVERAGE($E$7:$P$7) -> 0.85154443 | E11: =IF(OR(E$4="",E$4=0),"",SUM(E7:E10)) -> 2939430.4 | F11: =IF(OR(F$4="",F$4=0),"",SUM(F7:F10)) -> 3006659.3 | G11: =IF(OR(G$4="",G$4=0),"",SUM(G7:G10)) -> 3085836.7 | H11: =IF(OR(H$4="",H$4=0),"",SUM(H7:H10)) -> 3131996.7 | I11: =IF(OR(I$4="",I$4=0),"",SUM(I7:I10)) -> 3178847.9 | J11: =IF(OR(J$4="",J$4=0),"",SUM(J7:J10)) -> 3226400.5 | K11: =IF(OR(K$4="",K$4=0),"",SUM(K7:K10)) -> 3274665.2 | L11: =IF(OR(L$4="",L$4=0),"",SUM(L7:L10)) -> 3323652.4 | ... S11: =IF(OR(S$4="",S$4=0),"",SUM(S7:S10)) -> 3687728
B13: - Marketing | E13: =IF(OR(E$4="",E$4=0),"",-ABS(Expenses!E6)) -> -24000 | F13: =IF(OR(F$4="",F$4=0),"",-ABS(Expenses!F6)) -> -24720 | G13: =IF(OR(G$4="",G$4=0),"",-ABS(Expenses!G6)) -> -25461.6 | H13: =IF(OR(H$4="",H$4=0),"",-ABS(Expenses!H6)) -> -26225.448 | I13: =IF(OR(I$4="",I$4=0),"",-ABS(Expenses!I6)) -> -27012.211 | J13: =IF(OR(J$4="",J$4=0),"",-ABS(Expenses!J6)) -> -27822.578 | K13: =IF(OR(K$4="",K$4=0),"",-ABS(Expenses!K6)) -> -28657.255 | L13: =IF(OR(L$4="",L$4=0),"",-ABS(Expenses!L6)) -> -29516.973 | ... S13: =IF(OR(S$4="",S$4=0),"",-ABS(Expenses!S6)) -> -36302.153
B14: - Administrative | E14: =IF(OR(E$4="",E$4=0),"",-ABS(Expenses!E7)) -> -33000 | F14: =IF(OR(F$4="",F$4=0),"",-ABS(Expenses!F7)) -> -33990 | G14: =IF(OR(G$4="",G$4=0),"",-ABS(Expenses!G7)) -> -35009.7 | H14: =IF(OR(H$4="",H$4=0),"",-ABS(Expenses!H7)) -> -36059.991 | I14: =IF(OR(I$4="",I$4=0),"",-ABS(Expenses!I7)) -> -37141.791 | J14: =IF(OR(J$4="",J$4=0),"",-ABS(Expenses!J7)) -> -38256.044 | K14: =IF(OR(K$4="",K$4=0),"",-ABS(Expenses!K7)) -> -39403.726 | L14: =IF(OR(L$4="",L$4=0),"",-ABS(Expenses!L7)) -> -40585.838 | ... S14: =IF(OR(S$4="",S$4=0),"",-ABS(Expenses!S7)) -> -49915.461
B15: - Utilities | E15: =IF(OR(E$4="",E$4=0),"",-ABS(Expenses!E8)) -> -99000 | F15: =IF(OR(F$4="",F$4=0),"",-ABS(Expenses!F8)) -> -101970 | G15: =IF(OR(G$4="",G$4=0),"",-ABS(Expenses!G8)) -> -105029.1 | H15: =IF(OR(H$4="",H$4=0),"",-ABS(Expenses!H8)) -> -108179.97 | I15: =IF(OR(I$4="",I$4=0),"",-ABS(Expenses!I8)) -> -111425.37 | J15: =IF(OR(J$4="",J$4=0),"",-ABS(Expenses!J8)) -> -114768.13 | K15: =IF(OR(K$4="",K$4=0),"",-ABS(Expenses!K8)) -> -118211.18 | L15: =IF(OR(L$4="",L$4=0),"",-ABS(Expenses!L8)) -> -121757.51 | ... S15: =IF(OR(S$4="",S$4=0),"",-ABS(Expenses!S8)) -> -149746.38
B16: - Payroll | E16: =IF(OR(E$4="",E$4=0),"",-ABS(Expenses!E9)) -> -152000 | F16: =IF(OR(F$4="",F$4=0),"",-ABS(Expenses!F9)) -> -156560 | G16: =IF(OR(G$4="",G$4=0),"",-ABS(Expenses!G9)) -> -161256.8 | H16: =IF(OR(H$4="",H$4=0),"",-ABS(Expenses!H9)) -> -166094.5 | I16: =IF(OR(I$4="",I$4=0),"",-ABS(Expenses!I9)) -> -171077.34 | J16: =IF(OR(J$4="",J$4=0),"",-ABS(Expenses!J9)) -> -176209.66 | K16: =IF(OR(K$4="",K$4=0),"",-ABS(Expenses!K9)) -> -181495.95 | L16: =IF(OR(L$4="",L$4=0),"",-ABS(Expenses!L9)) -> -186940.83 | ... S16: =IF(OR(S$4="",S$4=0),"",-ABS(Expenses!S9)) -> -229913.64
B17: - Repair and maintenance | E17: =IF(OR(E$4="",E$4=0),"",-ABS(Expenses!E10)) -> -84400 | F17: =IF(OR(F$4="",F$4=0),"",-ABS(Expenses!F10)) -> -86932 | G17: =IF(OR(G$4="",G$4=0),"",-ABS(Expenses!G10)) -> -89539.96 | H17: =IF(OR(H$4="",H$4=0),"",-ABS(Expenses!H10)) -> -92226.159 | I17: =IF(OR(I$4="",I$4=0),"",-ABS(Expenses!I10)) -> -94992.944 | J17: =IF(OR(J$4="",J$4=0),"",-ABS(Expenses!J10)) -> -97842.732 | K17: =IF(OR(K$4="",K$4=0),"",-ABS(Expenses!K10)) -> -100778.01 | L17: =IF(OR(L$4="",L$4=0),"",-ABS(Expenses!L10)) -> -103801.35 | ... S17: =IF(OR(S$4="",S$4=0),"",-ABS(Expenses!S10)) -> -127662.57
B18: - Management (as % of EGR) | E18: =IF(OR(E$4="",E$4=0),"",-ABS(Expenses!E11)) -> -88182.912 | F18: =IF(OR(F$4="",F$4=0),"",-ABS(Expenses!F11)) -> -90828.399 | G18: =IF(OR(G$4="",G$4=0),"",-ABS(Expenses!G11)) -> -93553.251 | H18: =IF(OR(H$4="",H$4=0),"",-ABS(Expenses!H11)) -> -96359.849 | I18: =IF(OR(I$4="",I$4=0),"",-ABS(Expenses!I11)) -> -99250.644 | J18: =IF(OR(J$4="",J$4=0),"",-ABS(Expenses!J11)) -> -102228.16 | K18: =IF(OR(K$4="",K$4=0),"",-ABS(Expenses!K11)) -> -105295.01 | L18: =IF(OR(L$4="",L$4=0),"",-ABS(Expenses!L11)) -> -108453.86 | ... S18: =IF(OR(S$4="",S$4=0),"",-ABS(Expenses!S11)) -> -133384.57
B19: - Insurance | E19: =IF(OR(E$4="",E$4=0),"",-ABS(Expenses!E12)) -> -39000 | F19: =IF(OR(F$4="",F$4=0),"",-ABS(Expenses!F12)) -> -40170 | G19: =IF(OR(G$4="",G$4=0),"",-ABS(Expenses!G12)) -> -41375.1 | H19: =IF(OR(H$4="",H$4=0),"",-ABS(Expenses!H12)) -> -42616.353 | I19: =IF(OR(I$4="",I$4=0),"",-ABS(Expenses!I12)) -> -43894.844 | J19: =IF(OR(J$4="",J$4=0),"",-ABS(Expenses!J12)) -> -45211.689 | K19: =IF(OR(K$4="",K$4=0),"",-ABS(Expenses!K12)) -> -46568.04 | L19: =IF(OR(L$4="",L$4=0),"",-ABS(Expenses!L12)) -> -47965.081 | ... S19: =IF(OR(S$4="",S$4=0),"",-ABS(Expenses!S12)) -> -58990.999
B20: - Taxes | E20: =IF(OR(E$4="",E$4=0),"",-ABS(Expenses!E13)) -> -120000 | F20: =IF(OR(F$4="",F$4=0),"",-ABS(Expenses!F13)) -> -123600 | G20: =IF(OR(G$4="",G$4=0),"",-ABS(Expenses!G13)) -> -127308 | H20: =IF(OR(H$4="",H$4=0),"",-ABS(Expenses!H13)) -> -131127.24 | I20: =IF(OR(I$4="",I$4=0),"",-ABS(Expenses!I13)) -> -135061.06 | J20: =IF(OR(J$4="",J$4=0),"",-ABS(Expenses!J13)) -> -139112.89 | K20: =IF(OR(K$4="",K$4=0),"",-ABS(Expenses!K13)) -> -143286.28 | L20: =IF(OR(L$4="",L$4=0),"",-ABS(Expenses!L13)) -> -147584.86 | ... S20: =IF(OR(S$4="",S$4=0),"",-ABS(Expenses!S13)) -> -181510.77
B21: Operating Expenses | D21: =-AVERAGE(E21:P21)/AVERAGE($E$7:$P$7) -> 0.19835989 | E21: =IF(OR(E$4="",E$4=0),"",-ABS(Expenses!E14)) -> -639582.91 | F21: =IF(OR(F$4="",F$4=0),"",-ABS(Expenses!F14)) -> -658770.4 | G21: =IF(OR(G$4="",G$4=0),"",-ABS(Expenses!G14)) -> -678533.51 | H21: =IF(OR(H$4="",H$4=0),"",-ABS(Expenses!H14)) -> -698889.52 | I21: =IF(OR(I$4="",I$4=0),"",-ABS(Expenses!I14)) -> -719856.2 | J21: =IF(OR(J$4="",J$4=0),"",-ABS(Expenses!J14)) -> -741451.89 | K21: =IF(OR(K$4="",K$4=0),"",-ABS(Expenses!K14)) -> -763695.44 | L21: =IF(OR(L$4="",L$4=0),"",-ABS(Expenses!L14)) -> -786606.31 | ... S21: =IF(OR(S$4="",S$4=0),"",-ABS(Expenses!S14)) -> -967426.54
B23: Net Operating Income | D23: =AVERAGE(E23:P23)/AVERAGE($E$7:$P$7) -> 0.65318455 | E23: =IF(OR(E$4="",E$4=0),"",SUM(E11,E21)) -> 2299847.5 | F23: =IF(OR(F$4="",F$4=0),"",SUM(F11,F21)) -> 2347888.9 | G23: =IF(OR(G$4="",G$4=0),"",SUM(G11,G21)) -> 2407303.2 | H23: =IF(OR(H$4="",H$4=0),"",SUM(H11,H21)) -> 2433107.2 | I23: =IF(OR(I$4="",I$4=0),"",SUM(I11,I21)) -> 2458991.7 | J23: =IF(OR(J$4="",J$4=0),"",SUM(J11,J21)) -> 2484948.6 | K23: =IF(OR(K$4="",K$4=0),"",SUM(K11,K21)) -> 2510969.7 | L23: =IF(OR(L$4="",L$4=0),"",SUM(L11,L21)) -> 2537046.1 | ... S23: =IF(OR(S$4="",S$4=0),"",SUM(S11,S21)) -> 2720301.5
B25: - Releasing Costs | E25: =IF(OR(E$4="",E$4=0),"",-SUMIF(Calculations!$C$75:$FZ$75,E$4,Calculations!$C$84:$FZ$84)) -> 0 | F25: =IF(OR(F$4="",F$4=0),"",-SUMIF(Calculations!$C$75:$FZ$75,F$4,Calculations!$C$84:$FZ$84)) -> -15912 | G25: =IF(OR(G$4="",G$4=0),"",-SUMIF(Calculations!$C$75:$FZ$75,G$4,Calculations!$C$84:$FZ$84)) -> -16230.24 | H25: =IF(OR(H$4="",H$4=0),"",-SUMIF(Calculations!$C$75:$FZ$75,H$4,Calculations!$C$84:$FZ$84)) -> -16554.845 | I25: =IF(OR(I$4="",I$4=0),"",-SUMIF(Calculations!$C$75:$FZ$75,I$4,Calculations!$C$84:$FZ$84)) -> -16885.942 | J25: =IF(OR(J$4="",J$4=0),"",-SUMIF(Calculations!$C$75:$FZ$75,J$4,Calculations!$C$84:$FZ$84)) -> -17223.661 | K25: =IF(OR(K$4="",K$4=0),"",-SUMIF(Calculations!$C$75:$FZ$75,K$4,Calculations!$C$84:$FZ$84)) -> -17568.134 | L25: =IF(OR(L$4="",L$4=0),"",-SUMIF(Calculations!$C$75:$FZ$75,L$4,Calculations!$C$84:$FZ$84)) -> -17919.496 | ... S25: =IF(OR(S$4="",S$4=0),"",-SUMIF(Calculations!$C$75:$FZ$75,S$4,Calculations!$C$84:$FZ$84)) -> -20583.869
B26: - Value Add Costs | E26: =IF(OR(E$4="",E$4=0),"",Expenses!E20) -> -350000 | F26: =IF(OR(F$4="",F$4=0),"",Expenses!F20) -> -200000 | G26: =IF(OR(G$4="",G$4=0),"",Expenses!G20) -> 0 | H26: =IF(OR(H$4="",H$4=0),"",Expenses!H20) -> 0 | I26: =IF(OR(I$4="",I$4=0),"",Expenses!I20) -> 0 | J26: =IF(OR(J$4="",J$4=0),"",Expenses!J20) -> 0 | K26: =IF(OR(K$4="",K$4=0),"",Expenses!K20) -> 0 | L26: =IF(OR(L$4="",L$4=0),"",Expenses!L20) -> 0 | ... S26: =IF(OR(S$4="",S$4=0),"",Expenses!S20) -> 0
B27: - Misc. CapEx | E27: =IF(OR(E$4="",E$4=0),"",-SUMIF(Calculations!$C$25:$FZ$25,E$4,Calculations!$C$34:$FZ$34)) -> -97200 | F27: =IF(OR(F$4="",F$4=0),"",-SUMIF(Calculations!$C$25:$FZ$25,F$4,Calculations!$C$34:$FZ$34)) -> -99630 | G27: =IF(OR(G$4="",G$4=0),"",-SUMIF(Calculations!$C$25:$FZ$25,G$4,Calculations!$C$34:$FZ$34)) -> -102120.75 | H27: =IF(OR(H$4="",H$4=0),"",-SUMIF(Calculations!$C$25:$FZ$25,H$4,Calculations!$C$34:$FZ$34)) -> -104673.77 | I27: =IF(OR(I$4="",I$4=0),"",-SUMIF(Calculations!$C$25:$FZ$25,I$4,Calculations!$C$34:$FZ$34)) -> -107290.61 | J27: =IF(OR(J$4="",J$4=0),"",-SUMIF(Calculations!$C$25:$FZ$25,J$4,Calculations!$C$34:$FZ$34)) -> -109972.88 | K27: =IF(OR(K$4="",K$4=0),"",-SUMIF(Calculations!$C$25:$FZ$25,K$4,Calculations!$C$34:$FZ$34)) -> -112722.2 | L27: =IF(OR(L$4="",L$4=0),"",-SUMIF(Calculations!$C$25:$FZ$25,L$4,Calculations!$C$34:$FZ$34)) -> -115540.26 | ... S27: =IF(OR(S$4="",S$4=0),"",-SUMIF(Calculations!$C$25:$FZ$25,S$4,Calculations!$C$34:$FZ$34)) -> -137341.06
B28: Capital Expenditures | D28: =-AVERAGE(E28:P28)/AVERAGE($E$7:$P$7) -> 0.045553959 | E28: =IF(OR(E$4="",E$4=0),"",SUM(E25:E27)) -> -447200 | F28: =IF(OR(F$4="",F$4=0),"",SUM(F25:F27)) -> -315542 | G28: =IF(OR(G$4="",G$4=0),"",SUM(G25:G27)) -> -118350.99 | H28: =IF(OR(H$4="",H$4=0),"",SUM(H25:H27)) -> -121228.61 | I28: =IF(OR(I$4="",I$4=0),"",SUM(I25:I27)) -> -124176.55 | J28: =IF(OR(J$4="",J$4=0),"",SUM(J25:J27)) -> -127196.54 | K28: =IF(OR(K$4="",K$4=0),"",SUM(K25:K27)) -> -130290.33 | L28: =IF(OR(L$4="",L$4=0),"",SUM(L25:L27)) -> -133459.75 | ... S28: =IF(OR(S$4="",S$4=0),"",SUM(S25:S27)) -> -157924.92
B30: Cash Flow From Operations | D30: =AVERAGE(E30:P30)/AVERAGE($E$7:$P$7) -> 0.60763059 | E30: =IF(OR(E$4="",E$4=0),"",SUM(E23,E28)) -> 1852647.5 | F30: =IF(OR(F$4="",F$4=0),"",SUM(F23,F28)) -> 2032346.9 | G30: =IF(OR(G$4="",G$4=0),"",SUM(G23,G28)) -> 2288952.2 | H30: =IF(OR(H$4="",H$4=0),"",SUM(H23,H28)) -> 2311878.6 | I30: =IF(OR(I$4="",I$4=0),"",SUM(I23,I28)) -> 2334815.1 | J30: =IF(OR(J$4="",J$4=0),"",SUM(J23,J28)) -> 2357752.1 | K30: =IF(OR(K$4="",K$4=0),"",SUM(K23,K28)) -> 2380679.4 | L30: =IF(OR(L$4="",L$4=0),"",SUM(L23,L28)) -> 2403586.4 | ... S30: =IF(OR(S$4="",S$4=0),"",SUM(S23,S28)) -> 2562376.6

Sheet Property Returns
B2: Property Level Returns
D4: 1 | E4: =IF(OR(D4="",D4=Terminal_Cap_Year),"",D4+1) -> 2 | F4: =IF(OR(E4="",E4=Terminal_Cap_Year),"",E4+1) -> 3 | G4: =IF(OR(F4="",F4=Terminal_Cap_Year),"",F4+1) -> 4 | H4: =IF(OR(G4="",G4=Terminal_Cap_Year),"",G4+1) -> 5 | I4: =IF(OR(H4="",H4=Terminal_Cap_Year),"",H4+1) -> 6 | J4: =IF(OR(I4="",I4=Terminal_Cap_Year),"",I4+1) -> 7 | K4: =IF(OR(J4="",J4=Terminal_Cap_Year),"",J4+1) -> 8 | L4: =IF(OR(K4="",K4=Terminal_Cap_Year),"",K4+1) -> 9 | ... R4: =IF(OR(Q4="",Q4=Terminal_Cap_Year),"",Q4+1) -> 15
C5: Year Ending | D5: =EOMONTH(Analysis_Start,11) -> 44196 | E5: =EOMONTH(Analysis_Start,11) -> 44196 | F5: =IF(F4="","",EOMONTH(Analysis_Start,(11*F4)+E4)) -> 44926 | G5: =IF(G4="","",EOMONTH(Analysis_Start,(11*G4)+F4)) -> 45291 | H5: =IF(H4="","",EOMONTH(Analysis_Start,(11*H4)+G4)) -> 45657 | I5: =IF(I4="","",EOMONTH(Analysis_Start,(11*I4)+H4)) -> 46022 | J5: =IF(J4="","",EOMONTH(Analysis_Start,(11*J4)+I4)) -> 46387 | K5: =IF(K4="","",EOMONTH(Analysis_Start,(11*K4)+J4)) -> 46752 | L5: =IF(L4="","",EOMONTH(Analysis_Start,(11*L4)+K4)) -> 47118 | M5: =IF(M4="","",EOMONTH(Analysis_Start,(11*M4)+L4)) -> 47483 | ... R5: =IF(R4="","",EOMONTH(Analysis_Start,(11*R4)+Q4)) -> 49309
B6: Effective Gross Revenue | D6: =IF(OR(D$4="",D$4=0),"",'Annual Cash Flow'!E11) -> 2939430.4 | E6: =IF(OR(E$4="",E$4=0),"",'Annual Cash Flow'!F11) -> 3006659.3 | F6: =IF(OR(F$4="",F$4=0),"",'Annual Cash Flow'!G11) -> 3085836.7 | G6: =IF(OR(G$4="",G$4=0),"",'Annual Cash Flow'!H11) -> 3131996.7 | H6: =IF(OR(H$4="",H$4=0),"",'Annual Cash Flow'!I11) -> 3178847.9 | I6: =IF(OR(I$4="",I$4=0),"",'Annual Cash Flow'!J11) -> 3226400.5 | J6: =IF(OR(J$4="",J$4=0),"",'Annual Cash Flow'!K11) -> 3274665.2 | K6: =IF(OR(K$4="",K$4=0),"",'Annual Cash Flow'!L11) -> 3323652.4 | ... R6: =IF(OR(R$4="",R$4=0),"",'Annual Cash Flow'!S11) -> 3687728
B7: Operating Expenses | D7: =IF(OR(D$4="",D$4=0),"",'Annual Cash Flow'!E21) -> -639582.91 | E7: =IF(OR(E$4="",E$4=0),"",'Annual Cash Flow'!F21) -> -658770.4 | F7: =IF(OR(F$4="",F$4=0),"",'Annual Cash Flow'!G21) -> -678533.51 | G7: =IF(OR(G$4="",G$4=0),"",'Annual Cash Flow'!H21) -> -698889.52 | H7: =IF(OR(H$4="",H$4=0),"",'Annual Cash Flow'!I21) -> -719856.2 | I7: =IF(OR(I$4="",I$4=0),"",'Annual Cash Flow'!J21) -> -741451.89 | J7: =IF(OR(J$4="",J$4=0),"",'Annual Cash Flow'!K21) -> -763695.44 | K7: =IF(OR(K$4="",K$4=0),"",'Annual Cash Flow'!L21) -> -786606.31 | ... R7: =IF(OR(R$4="",R$4=0),"",'Annual Cash Flow'!S21) -> -967426.54
B8: Net Operating Income | D8: =IF(OR(D$4="",D$4=0),"",'Annual Cash Flow'!E23) -> 2299847.5 | E8: =IF(OR(E$4="",E$4=0),"",'Annual Cash Flow'!F23) -> 2347888.9 | F8: =IF(OR(F$4="",F$4=0),"",'Annual Cash Flow'!G23) -> 2407303.2 | G8: =IF(OR(G$4="",G$4=0),"",'Annual Cash Flow'!H23) -> 2433107.2 | H8: =IF(OR(H$4="",H$4=0),"",'Annual Cash Flow'!I23) -> 2458991.7 | I8: =IF(OR(I$4="",I$4=0),"",'Annual Cash Flow'!J23) -> 2484948.6 | J8: =IF(OR(J$4="",J$4=0),"",'Annual Cash Flow'!K23) -> 2510969.7 | K8: =IF(OR(K$4="",K$4=0),"",'Annual Cash Flow'!L23) -> 2537046.1 | ... R8: =IF(OR(R$4="",R$4=0),"",'Annual Cash Flow'!S23) -> 2720301.5
B9: Capital Expenditures | D9: =IF(OR(D$4="",D$4=0),"",'Annual Cash Flow'!E28) -> -447200 | E9: =IF(OR(E$4="",E$4=0),"",'Annual Cash Flow'!F28) -> -315542 | F9: =IF(OR(F$4="",F$4=0),"",'Annual Cash Flow'!G28) -> -118350.99 | G9: =IF(OR(G$4="",G$4=0),"",'Annual Cash Flow'!H28) -> -121228.61 | H9: =IF(OR(H$4="",H$4=0),"",'Annual Cash Flow'!I28) -> -124176.55 | I9: =IF(OR(I$4="",I$4=0),"",'Annual Cash Flow'!J28) -> -127196.54 | J9: =IF(OR(J$4="",J$4=0),"",'Annual Cash Flow'!K28) -> -130290.33 | K9: =IF(OR(K$4="",K$4=0),"",'Annual Cash Flow'!L28) -> -133459.75 | ... R9: =IF(OR(R$4="",R$4=0),"",'Annual Cash Flow'!S28) -> -157924.92
B10: Cash Flow From Operations | D10: =IF(OR(D$4="",D$4=0),"",'Annual Cash Flow'!E30) -> 1852647.5 | E10: =IF(OR(E$4="",E$4=0),"",'Annual Cash Flow'!F30) -> 2032346.9 | F10: =IF(OR(F$4="",F$4=0),"",'Annual Cash Flow'!G30) -> 2288952.2 | G10: =IF(OR(G$4="",G$4=0),"",'Annual Cash Flow'!H30) -> 2311878.6 | H10: =IF(OR(H$4="",H$4=0),"",'Annual Cash Flow'!I30) -> 2334815.1 | I10: =IF(OR(I$4="",I$4=0),"",'Annual Cash Flow'!J30) -> 2357752.1 | J10: =IF(OR(J$4="",J$4=0),"",'Annual Cash Flow'!K30) -> 2380679.4 | K10: =IF(OR(K$4="",K$4=0),"",'Annual Cash Flow'!L30) -> 2403586.4 | ... R10: =IF(OR(R$4="",R$4=0),"",'Annual Cash Flow'!S30) -> 2562376.6
B12: Cap Rate at Sale | D12: ='Property Summary'!$C$11 -> 0.065 | E12: =IF(OR(E$4="",E$4=0),"",IF(E$4>Effective_Hold_Period,"",(D$12+('Property Summary'!$C$10/10000)))) -> 0.0655 | F12: =IF(OR(F$4="",F$4=0),"",IF(F$4>Effective_Hold_Period,"",(E$12+('Property Summary'!$C$10/10000)))) -> 0.066 | G12: =IF(OR(G$4="",G$4=0),"",IF(G$4>Effective_Hold_Period,"",(F$12+('Property Summary'!$C$10/10000)))) -> 0.0665 | H12: =IF(OR(H$4="",H$4=0),"",IF(H$4>Effective_Hold_Period,"",(G$12+('Property Summary'!$C$10/10000)))) -> 0.067 | I12: =IF(OR(I$4="",I$4=0),"",IF(I$4>Effective_Hold_Period,"",(H$12+('Property Summary'!$C$10/10000)))) -> 0.0675 | J12: =IF(OR(J$4="",J$4=0),"",IF(J$4>Effective_Hold_Period,"",(I$12+('Property Summary'!$C$10/10000)))) -> 0.068 | K12: =IF(OR(K$4="",K$4=0),"",IF(K$4>Effective_Hold_Period,"",(J$12+('Property Summary'!$C$10/10000)))) -> 0.0685 | L12: =IF(OR(L$4="",L$4=0),"",IF(L$4>Effective_Hold_Period,"",(K$12+('Property Summary'!$C$10/10000)))) -> 0.069 | ... R12: =IF(OR(R$4="",R$4=0),"",IF(R$4>Effective_Hold_Period,"",(Q$12+('Property Summary'!$C$10/10000)))) -> 0.072
B13: Net Sales Price | D13: =IFERROR(HLOOKUP(Terminal_Cap_Year-Effective_Hold_Period+D$4,$D$4:$R$10,5,FALSE)/D$12,"") -> 35382269 | E13: =IFERROR(HLOOKUP(Terminal_Cap_Year-Effective_Hold_Period+E$4,$D$4:$R$10,5,FALSE)/E$12,"") -> 35845632 | F13: =IFERROR(HLOOKUP(Terminal_Cap_Year-Effective_Hold_Period+F$4,$D$4:$R$10,5,FALSE)/F$12,"") -> 36474291 | G13: =IFERROR(HLOOKUP(Terminal_Cap_Year-Effective_Hold_Period+G$4,$D$4:$R$10,5,FALSE)/G$12,"") -> 36588078 | H13: =IFERROR(HLOOKUP(Terminal_Cap_Year-Effective_Hold_Period+H$4,$D$4:$R$10,5,FALSE)/H$12,"") -> 36701368 | I13: =IFERROR(HLOOKUP(Terminal_Cap_Year-Effective_Hold_Period+I$4,$D$4:$R$10,5,FALSE)/I$12,"") -> 36814054 | J13: =IFERROR(HLOOKUP(Terminal_Cap_Year-Effective_Hold_Period+J$4,$D$4:$R$10,5,FALSE)/J$12,"") -> 36926025 | K13: =IFERROR(HLOOKUP(Terminal_Cap_Year-Effective_Hold_Period+K$4,$D$4:$R$10,5,FALSE)/K$12,"") -> 37037170 | ... R13: =IFERROR(HLOOKUP(Terminal_Cap_Year-Effective_Hold_Period+R$4,$D$4:$R$10,5,FALSE)/R$12,"") -> 37781965
B14: ="Net Sales Price Per "&'Property Summary'!$I$26 -> Net Sales Price Per SQFT | D14: =IFERROR(IF(OR(D$4="",D$4=0),"",D13/'Property Summary'!$I$27),"") -> 565.93521 | E14: =IFERROR(IF(OR(E$4="",E$4=0),"",E13/'Property Summary'!$I$27),"") -> 573.34664 | F14: =IFERROR(IF(OR(F$4="",F$4=0),"",F13/'Property Summary'!$I$27),"") -> 583.40196 | G14: =IFERROR(IF(OR(G$4="",G$4=0),"",G13/'Property Summary'!$I$27),"") -> 585.22198 | H14: =IFERROR(IF(OR(H$4="",H$4=0),"",H13/'Property Summary'!$I$27),"") -> 587.03404 | I14: =IFERROR(IF(OR(I$4="",I$4=0),"",I13/'Property Summary'!$I$27),"") -> 588.83644 | J14: =IFERROR(IF(OR(J$4="",J$4=0),"",J13/'Property Summary'!$I$27),"") -> 590.6274 | K14: =IFERROR(IF(OR(K$4="",K$4=0),"",K13/'Property Summary'!$I$27),"") -> 592.40515 | ... R14: =IFERROR(IF(OR(R$4="",R$4=0),"",R13/'Property Summary'!$I$27),"") -> 604.31806
B16: Cash Flow from Operations | D16: =IF(D$4>Analysis_Period,"",D$10) -> 1852647.5 | E16: =IF(E$4>Analysis_Period,"",E$10) -> 2032346.9 | F16: =IF(F$4>Analysis_Period,"",F$10) -> 2288952.2 | G16: =IF(G$4>Analysis_Period,"",G$10) -> 2311878.6 | H16: =IF(H$4>Analysis_Period,"",H$10) -> 2334815.1 | I16: =IF(I$4>Analysis_Period,"",I$10) -> 2357752.1 | J16: =IF(J$4>Analysis_Period,"",J$10) -> 2380679.4 | K16: =IF(K$4>Analysis_Period,"",K$10) -> 2403586.4 | ... R16: =IF(R$4>Analysis_Period,"",R$10) -> 2562376.6
B17: Free and Clear Return | D17: =IF(D$10="","",D$10/-D$50) -> 0.051564425 | E17: =IF(E$10="","",IF(E$4>Effective_Hold_Period,"",E$10/-E$50)) -> 0.056565969 | F17: =IF(F$10="","",IF(F$4>Effective_Hold_Period,"",F$10/-F$50)) -> 0.06370802 | G17: =IF(G$10="","",IF(G$4>Effective_Hold_Period,"",G$10/-G$50)) -> 0.064346127 | H17: =IF(H$10="","",IF(H$4>Effective_Hold_Period,"",H$10/-H$50)) -> 0.064984516 | I17: =IF(I$10="","",IF(I$4>Effective_Hold_Period,"",I$10/-I$50)) -> 0.065622917 | J17: =IF(J$10="","",IF(J$4>Effective_Hold_Period,"",J$10/-J$50)) -> 0.066261048 | K17: =IF(K$10="","",IF(K$4>Effective_Hold_Period,"",K$10/-K$50)) -> 0.066898615 | L17: =IF(L$10="","",IF(L$4>Effective_Hold_Period,"",L$10/-L$50)) -> 0.06753531 | ... R17: =IF(R$10="","",IF(R$4>Effective_Hold_Period,"",R$10/-R$50)) -> 0.071318194
B18: Avg. Free and Clear Return | D18: =IF(D17="","",AVERAGE($D$17:D$17)) -> 0.051564425 | E18: =IF(E17="","",AVERAGE($D$17:E$17)) -> 0.054065197 | F18: =IF(F17="","",AVERAGE($D$17:F$17)) -> 0.057279471 | G18: =IF(G17="","",AVERAGE($D$17:G$17)) -> 0.059046135 | H18: =IF(H17="","",AVERAGE($D$17:H$17)) -> 0.060233811 | I18: =IF(I17="","",AVERAGE($D$17:I$17)) -> 0.061131995 | J18: =IF(J17="","",AVERAGE($D$17:J$17)) -> 0.061864717 | K18: =IF(K17="","",AVERAGE($D$17:K$17)) -> 0.062493954 | ... R18: =IF(R17="","",AVERAGE($D$17:R$17)) -> 0.065731889
B19: Unlevered CF w/ Residual | D19: =IF(D4=Analysis_Period,D$13+D$16,D$16) -> 1852647.5 | E19: =IF(E4=Analysis_Period,E$13+E$16,E$16) -> 2032346.9 | F19: =IF(F4=Analysis_Period,F$13+F$16,F$16) -> 2288952.2 | G19: =IF(G4=Analysis_Period,G$13+G$16,G$16) -> 2311878.6 | H19: =IF(H4=Analysis_Period,H$13+H$16,H$16) -> 2334815.1 | I19: =IF(I4=Analysis_Period,I$13+I$16,I$16) -> 2357752.1 | J19: =IF(J4=Analysis_Period,J$13+J$16,J$16) -> 2380679.4 | K19: =IF(K4=Analysis_Period,K$13+K$16,K$16) -> 2403586.4 | ... R19: =IF(R4=Analysis_Period,R$13+R$16,R$16) -> 40344342
B21: Unlevered IRR | D21: =IF(D4>Analysis_Period,"",D49) -> 0.036353151 | E21: =IF(E4>Analysis_Period,"",E49) -> 0.05287331 | F21: =IF(F4>Analysis_Period,"",F49) -> 0.061797984 | G21: =IF(G4>Analysis_Period,"",G49) -> 0.062874554 | H21: =IF(H4>Analysis_Period,"",H49) -> 0.063589214 | I21: =IF(I4>Analysis_Period,"",I49) -> 0.06412065 | J21: =IF(J4>Analysis_Period,"",J49) -> 0.064545229 | K21: =IF(K4>Analysis_Period,"",K49) -> 0.064901085 | ... R21: =IF(R4>Analysis_Period,"",R49) -> 0.066536708
B22: Unlevered EM | D22: =IF(D$48="","",SUMIF(D50:D65,">0")/-SUMIF(D50:D65,"<0")) -> 1.0363532 | E22: =IF(E$48="","",SUMIF(E50:E65,">0")/-SUMIF(E50:E65,"<0")) -> 1.1058158 | F22: =IF(F$48="","",SUMIF(F50:F65,">0")/-SUMIF(F50:F65,"<0")) -> 1.1870212 | G22: =IF(G$48="","",SUMIF(G50:G65,">0")/-SUMIF(G50:G65,"<0")) -> 1.2545344 | H22: =IF(H$48="","",SUMIF(H50:H65,">0")/-SUMIF(H50:H65,"<0")) -> 1.3226721 | I22: =IF(I$48="","",SUMIF(I50:I65,">0")/-SUMIF(I50:I65,"<0")) -> 1.3914313 | J22: =IF(J$48="","",SUMIF(J50:J65,">0")/-SUMIF(J50:J65,"<0")) -> 1.4608089 | K22: =IF(K$48="","",SUMIF(K50:K65,">0")/-SUMIF(K50:K65,"<0")) -> 1.5308009 | ... R22: =IF(R$48="","",SUMIF(R50:R65,">0")/-SUMIF(R50:R65,"<0")) -> 2.0375574
B24: % of Total Cash from Operations | D24: =IFERROR(SUM($D$19:D$19)/(SUM($D$19:D$19)+D13),"") -> 0.04975565 | E24: =IFERROR(SUM($D$19:E$19)/(SUM($D$19:E$19)+E13),"") -> 0.097783366 | F24: =IFERROR(SUM($D$19:F$19)/(SUM($D$19:F$19)+F13),"") -> 0.1447644 | G24: =IFERROR(SUM($D$19:G$19)/(SUM($D$19:G$19)+G13),"") -> 0.18826471 | H24: =IFERROR(SUM($D$19:H$19)/(SUM($D$19:H$19)+H13),"") -> 0.22769745 | I24: =IFERROR(SUM($D$19:I$19)/(SUM($D$19:I$19)+I13),"") -> 0.26360767 | J24: =IFERROR(SUM($D$19:J$19)/(SUM($D$19:J$19)+J13),"") -> 0.29644742 | K24: =IFERROR(SUM($D$19:K$19)/(SUM($D$19:K$19)+K13),"") -> 0.32659481 | ... R24: =IFERROR(SUM($D$19:R$19)/(SUM($D$19:R$19)+R13),"") -> 0.65958802
B25: % of Total Cash from Sale | D25: =IFERROR(1-D24,"") -> 0.95024435 | E25: =IFERROR(1-E24,"") -> 0.90221663 | F25: =IFERROR(1-F24,"") -> 0.8552356 | G25: =IFERROR(1-G24,"") -> 0.81173529 | H25: =IFERROR(1-H24,"") -> 0.77230255 | I25: =IFERROR(1-I24,"") -> 0.73639233 | J25: =IFERROR(1-J24,"") -> 0.70355258 | K25: =IFERROR(1-K24,"") -> 0.67340519 | ... R25: =IFERROR(1-R24,"") -> 0.34041198
B27: Debt Service | D27: =Debt!D$6 -> 1331881 | E27: =Debt!E$6 -> 1331881 | F27: =Debt!F$6 -> 1331881 | G27: =Debt!G$6 -> 1331881 | H27: =Debt!H$6 -> 1331881 | I27: =Debt!I$6 -> 1331881 | J27: =Debt!J$6 -> 1331881 | K27: =Debt!K$6 -> 1331881 | ... R27: =Debt!R$6 -> 1331881
B28: Debt Service Coverage Ratio (NOI) | D28: =IFERROR(D$8/D$27,"") -> 1.7267665 | E28: =IFERROR(E$8/E$27,"") -> 1.7628369 | F28: =IFERROR(F$8/F$27,"") -> 1.8074462 | G28: =IFERROR(G$8/G$27,"") -> 1.8268203 | H28: =IFERROR(H$8/H$27,"") -> 1.8462548 | I28: =IFERROR(I$8/I$27,"") -> 1.8657438 | J28: =IFERROR(J$8/J$27,"") -> 1.8852809 | K28: =IFERROR(K$8/K$27,"") -> 1.9048595 | ... R28: =IFERROR(R$8/R$27,"") -> 2.0424509
B29: Debt Yield (NOI) | D29: =IFERROR(D$8/D$30,"") -> 0.12697548 | E29: =IFERROR(E$8/E$30,"") -> 0.12976655 | F29: =IFERROR(F$8/F$30,"") -> 0.13320353 | G29: =IFERROR(G$8/G$30,"") -> 0.13479819 | H29: =IFERROR(H$8/H$30,"") -> 0.13641395 | I29: =IFERROR(I$8/I$30,"") -> 0.13805187 | J29: =IFERROR(J$8/J$30,"") -> 0.13971314 | K29: =IFERROR(K$8/K$30,"") -> 0.14139904 | ... R29: =IFERROR(R$8/R$30,"") -> 0.15403424
B30: Loan Balance | D30: =Debt!D$7 -> 18112533 | E30: =Debt!E$7 -> 18093176 | F30: =Debt!F$7 -> 18072368 | G30: =Debt!G$7 -> 18050000 | H30: =Debt!H$7 -> 18025955 | I30: =Debt!I$7 -> 18000108 | J30: =Debt!J$7 -> 17972324 | K30: =Debt!K$7 -> 17942457 | ... R30: =Debt!R$7 -> 17660369
B32: Net Cash on Sale | D32: =IFERROR(D$13-D$30,"") -> 17269736 | E32: =IFERROR(E$13-E$30,"") -> 17752456 | F32: =IFERROR(F$13-F$30,"") -> 18401923 | G32: =IFERROR(G$13-G$30,"") -> 18538079 | H32: =IFERROR(H$13-H$30,"") -> 18675413 | I32: =IFERROR(I$13-I$30,"") -> 18813946 | J32: =IFERROR(J$13-J$30,"") -> 18953701 | K32: =IFERROR(K$13-K$30,"") -> 19094713 | ... R32: =IFERROR(R$13-R$30,"") -> 20121596
B33: Net Gain | D33: =IFERROR(D$32-(-D71),"") -> 18311269 | E33: =IFERROR(E$32-(-E71),"") -> 35022193 | F33: =IFERROR(F$32-(-F71),"") -> 35671659 | G33: =IFERROR(G$32-(-G71),"") -> 35807815 | H33: =IFERROR(H$32-(-H71),"") -> 35945150 | I33: =IFERROR(I$32-(-I71),"") -> 36083682 | J33: =IFERROR(J$32-(-J71),"") -> 36223438 | K33: =IFERROR(K$32-(-K71),"") -> 36364449 | ... R33: =IFERROR(R$32-(-R71),"") -> 37391332
B35: Cash Flow After Financing | D35: =IFERROR(D$10-D$27,"") -> 520766.52 | E35: =IFERROR(E$10-E$27,"") -> 700465.93 | F35: =IFERROR(F$10-F$27,"") -> 957071.22 | G35: =IFERROR(G$10-G$27,"") -> 979997.63 | H35: =IFERROR(H$10-H$27,"") -> 1002934.2 | I35: =IFERROR(I$10-I$27,"") -> 1025871.1 | J35: =IFERROR(J$10-J$27,"") -> 1048798.4 | K35: =IFERROR(K$10-K$27,"") -> 1071705.4 | ... R35: =IFERROR(R$10-R$27,"") -> 1230495.6
B36: Cash-on-Cash Return | D36: =IF(D35="","",D35/(-D70)) -> 0.026490261 | E36: =IF(E35="","",E35/(-E70)) -> 0.035631179 | F36: =IF(F35="","",F35/(-F70)) -> 0.048684132 | G36: =IF(G35="","",G35/(-G70)) -> 0.049850349 | H36: =IF(H35="","",H35/(-H70)) -> 0.051017081 | I36: =IF(I35="","",I35/(-I70)) -> 0.052183835 | J36: =IF(J35="","",J35/(-J70)) -> 0.053350095 | K36: =IF(K35="","",K35/(-K70)) -> 0.054515325 | ... R36: =IF(R35="","",R35/(-R70)) -> 0.062592636
B37: Avg. Cash-on-Cash Return | D37: =IF(D36="","",AVERAGE($D$36:D$36)) -> 0.026490261 | E37: =IF(E36="","",AVERAGE($D$36:E$36)) -> 0.03106072 | F37: =IF(F36="","",AVERAGE($D$36:F$36)) -> 0.036935191 | G37: =IF(G36="","",AVERAGE($D$36:G$36)) -> 0.04016398 | H37: =IF(H36="","",AVERAGE($D$36:H$36)) -> 0.0423346 | I37: =IF(I36="","",AVERAGE($D$36:I$36)) -> 0.043976139 | J37: =IF(J36="","",AVERAGE($D$36:J$36)) -> 0.045315276 | K37: =IF(K36="","",AVERAGE($D$36:K$36)) -> 0.046465282 | ... R37: =IF(R36="","",AVERAGE($D$36:R$36)) -> 0.052382995
B39: Levered IRR | D39: =D$69 -> -0.94701948 | E39: =E$69 -> -0.046767434 | F39: =F$69 -> 0.51634898 | G39: =G$69 -> 0.73145868 | H39: =H$69 -> 0.82159013 | I39: =I$69 -> 0.86261375 | J39: =J$69 -> 0.88234595 | K39: =K$69 -> 0.89218105 | ... R39: =R$69 -> 0.90252903
B40: Levered EM | D40: =IF(D$48="","",SUMIF(D$70:D$85,">0")/-SUMIF(D$70:D$85,"<0")) -> 0.052980521 | E40: =IF(E$48="","",SUMIF(E$70:E$85,">0")/-SUMIF(E$70:E$85,"<0")) -> 0.9497363 | F40: =IF(F$48="","",SUMIF(F$70:F$85,">0")/-SUMIF(F$70:F$85,"<0")) -> 1.8788711 | G40: =IF(G$48="","",SUMIF(G$70:G$85,">0")/-SUMIF(G$70:G$85,"<0")) -> 2.8172693 | H40: =IF(H$48="","",SUMIF(H$70:H$85,">0")/-SUMIF(H$70:H$85,"<0")) -> 3.7625945 | I40: =IF(I$48="","",SUMIF(I$70:I$85,">0")/-SUMIF(I$70:I$85,"<0")) -> 4.7149057 | J40: =IF(J$48="","",SUMIF(J$70:J$85,">0")/-SUMIF(J$70:J$85,"<0")) -> 5.6742628 | K40: =IF(K$48="","",SUMIF(K$70:K$85,">0")/-SUMIF(K$70:K$85,"<0")) -> 6.6407268 | ... R40: =IF(R$48="","",SUMIF(R$70:R$85,">0")/-SUMIF(R$70:R$85,"<0")) -> 13.610558
B42: Levered Before Tax Cash Flow | D42: =IF(D$4=Effective_Hold_Period,D$32+D$35,D$35) -> 520766.52 | E42: =IF(E$4=Effective_Hold_Period,E$32+E$35,E$35) -> 700465.93 | F42: =IF(F$4=Effective_Hold_Period,F$32+F$35,F$35) -> 957071.22 | G42: =IF(G$4=Effective_Hold_Period,G$32+G$35,G$35) -> 979997.63 | H42: =IF(H$4=Effective_Hold_Period,H$32+H$35,H$35) -> 1002934.2 | I42: =IF(I$4=Effective_Hold_Period,I$32+I$35,I$35) -> 1025871.1 | J42: =IF(J$4=Effective_Hold_Period,J$32+J$35,J$35) -> 1048798.4 | K42: =IF(K$4=Effective_Hold_Period,K$32+K$35,K$35) -> 1071705.4 | ... R42: =IF(R$4=Effective_Hold_Period,R$32+R$35,R$35) -> 21352091
B46: Internal Rate of Return Calculations
B47: Unlevered
C48: Year | D48: =IF(OR(D$13="",D$13=0),"",D$4) -> 1 | E48: =IF(OR(E$13="",E$13=0),"",E$4) -> 2 | F48: =IF(OR(F$13="",F$13=0),"",F$4) -> 3 | G48: =IF(OR(G$13="",G$13=0),"",G$4) -> 4 | H48: =IF(OR(H$13="",H$13=0),"",H$4) -> 5 | I48: =IF(OR(I$13="",I$13=0),"",I$4) -> 6 | J48: =IF(OR(J$13="",J$13=0),"",J$4) -> 7 | K48: =IF(OR(K$13="",K$13=0),"",K$4) -> 8 | ... R48: =IF(OR(R$13="",R$13=0),"",R$4) -> 15
C49: IRR | D49: =IF(OR(D$48="",D$48=0),"",IF(AND(MIN(D$50:D$65)<0,MAX(D$50:D$65)>0),IRR(D$50:D$65))) -> 0.036353151 | E49: =IF(OR(E$48="",E$48=0),"",IF(AND(MIN(E$50:E$65)<0,MAX(E$50:E$65)>0),IRR(E$50:E$65))) -> 0.05287331 | F49: =IF(OR(F$48="",F$48=0),"",IF(AND(MIN(F$50:F$65)<0,MAX(F$50:F$65)>0),IRR(F$50:F$65))) -> 0.061797984 | G49: =IF(OR(G$48="",G$48=0),"",IF(AND(MIN(G$50:G$65)<0,MAX(G$50:G$65)>0),IRR(G$50:G$65))) -> 0.062874554 | H49: =IF(OR(H$48="",H$48=0),"",IF(AND(MIN(H$50:H$65)<0,MAX(H$50:H$65)>0),IRR(H$50:H$65))) -> 0.063589214 | I49: =IF(OR(I$48="",I$48=0),"",IF(AND(MIN(I$50:I$65)<0,MAX(I$50:I$65)>0),IRR(I$50:I$65))) -> 0.06412065 | J49: =IF(OR(J$48="",J$48=0),"",IF(AND(MIN(J$50:J$65)<0,MAX(J$50:J$65)>0),IRR(J$50:J$65))) -> 0.064545229 | K49: =IF(OR(K$48="",K$48=0),"",IF(AND(MIN(K$50:K$65)<0,MAX(K$50:K$65)>0),IRR(K$50:K$65))) -> 0.064901085 | ... R49: =IF(OR(R$48="",R$48=0),"",IF(AND(MIN(R$50:R$65)<0,MAX(R$50:R$65)>0),IRR(R$50:R$65))) -> 0.066536708
C50: 0 | D50: =IF(OR(D$48="",D$48=0),"",-Basis) -> -35928792 | E50: =IF(OR(E$48="",E$48=0),"",-Basis) -> -35928792 | F50: =IF(OR(F$48="",F$48=0),"",-Basis) -> -35928792 | G50: =IF(OR(G$48="",G$48=0),"",-Basis) -> -35928792 | H50: =IF(OR(H$48="",H$48=0),"",-Basis) -> -35928792 | I50: =IF(OR(I$48="",I$48=0),"",-Basis) -> -35928792 | J50: =IF(OR(J$48="",J$48=0),"",-Basis) -> -35928792 | K50: =IF(OR(K$48="",K$48=0),"",-Basis) -> -35928792 | ... R50: =IF(OR(R$48="",R$48=0),"",-Basis) -> -35928792
C51: =C50+1 -> 1 | D51: =IF($C51>D$48,"",IF(OR(D$48="",D$48=0),"",IF(D$48=$C51,OFFSET($D$16,0,$C50)+OFFSET($D$13,0,$C50),OFFSET($D$16,0,$C50)))) -> 37234917 | E51: =IF($C51>E$48,"",IF(OR(E$48="",E$48=0),"",IF(E$48=$C51,OFFSET($D$16,0,$C50)+OFFSET($D$13,0,$C50),OFFSET($D$16,0,$C50)))) -> 1852647.5 | F51: =IF($C51>F$48,"",IF(OR(F$48="",F$48=0),"",IF(F$48=$C51,OFFSET($D$16,0,$C50)+OFFSET($D$13,0,$C50),OFFSET($D$16,0,$C50)))) -> 1852647.5 | G51: =IF($C51>G$48,"",IF(OR(G$48="",G$48=0),"",IF(G$48=$C51,OFFSET($D$16,0,$C50)+OFFSET($D$13,0,$C50),OFFSET($D$16,0,$C50)))) -> 1852647.5 | H51: =IF($C51>H$48,"",IF(OR(H$48="",H$48=0),"",IF(H$48=$C51,OFFSET($D$16,0,$C50)+OFFSET($D$13,0,$C50),OFFSET($D$16,0,$C50)))) -> 1852647.5 | I51: =IF($C51>I$48,"",IF(OR(I$48="",I$48=0),"",IF(I$48=$C51,OFFSET($D$16,0,$C50)+OFFSET($D$13,0,$C50),OFFSET($D$16,0,$C50)))) -> 1852647.5 | J51: =IF($C51>J$48,"",IF(OR(J$48="",J$48=0),"",IF(J$48=$C51,OFFSET($D$16,0,$C50)+OFFSET($D$13,0,$C50),OFFSET($D$16,0,$C50)))) -> 1852647.5 | K51: =IF($C51>K$48,"",IF(OR(K$48="",K$48=0),"",IF(K$48=$C51,OFFSET($D$16,0,$C50)+OFFSET($D$13,0,$C50),OFFSET($D$16,0,$C50)))) -> 1852647.5 | ... R51: =IF($C51>R$48,"",IF(OR(R$48="",R$48=0),"",IF(R$48=$C51,OFFSET($D$16,0,$C50)+OFFSET($D$13,0,$C50),OFFSET($D$16,0,$C50)))) -> 1852647.5
C52: =C51+1 -> 2 | D52: =IF($C52>D$48,"",IF(OR(D$48="",D$48=0),"",IF(D$48=$C52,OFFSET($D$16,0,$C51)+OFFSET($D$13,0,$C51),OFFSET($D$16,0,$C51)))) | E52: =IF($C52>E$48,"",IF(OR(E$48="",E$48=0),"",IF(E$48=$C52,OFFSET($D$16,0,$C51)+OFFSET($D$13,0,$C51),OFFSET($D$16,0,$C51)))) -> 37877979 | F52: =IF($C52>F$48,"",IF(OR(F$48="",F$48=0),"",IF(F$48=$C52,OFFSET($D$16,0,$C51)+OFFSET($D$13,0,$C51),OFFSET($D$16,0,$C51)))) -> 2032346.9 | G52: =IF($C52>G$48,"",IF(OR(G$48="",G$48=0),"",IF(G$48=$C52,OFFSET($D$16,0,$C51)+OFFSET($D$13,0,$C51),OFFSET($D$16,0,$C51)))) -> 2032346.9 | H52: =IF($C52>H$48,"",IF(OR(H$48="",H$48=0),"",IF(H$48=$C52,OFFSET($D$16,0,$C51)+OFFSET($D$13,0,$C51),OFFSET($D$16,0,$C51)))) -> 2032346.9 | I52: =IF($C52>I$48,"",IF(OR(I$48="",I$48=0),"",IF(I$48=$C52,OFFSET($D$16,0,$C51)+OFFSET($D$13,0,$C51),OFFSET($D$16,0,$C51)))) -> 2032346.9 | J52: =IF($C52>J$48,"",IF(OR(J$48="",J$48=0),"",IF(J$48=$C52,OFFSET($D$16,0,$C51)+OFFSET($D$13,0,$C51),OFFSET($D$16,0,$C51)))) -> 2032346.9 | K52: =IF($C52>K$48,"",IF(OR(K$48="",K$48=0),"",IF(K$48=$C52,OFFSET($D$16,0,$C51)+OFFSET($D$13,0,$C51),OFFSET($D$16,0,$C51)))) -> 2032346.9 | ... R52: =IF($C52>R$48,"",IF(OR(R$48="",R$48=0),"",IF(R$48=$C52,OFFSET($D$16,0,$C51)+OFFSET($D$13,0,$C51),OFFSET($D$16,0,$C51)))) -> 2032346.9
C53: =C52+1 -> 3 | D53: =IF($C53>D$48,"",IF(OR(D$48="",D$48=0),"",IF(D$48=$C53,OFFSET($D$16,0,$C52)+OFFSET($D$13,0,$C52),OFFSET($D$16,0,$C52)))) | E53: =IF($C53>E$48,"",IF(OR(E$48="",E$48=0),"",IF(E$48=$C53,OFFSET($D$16,0,$C52)+OFFSET($D$13,0,$C52),OFFSET($D$16,0,$C52)))) | F53: =IF($C53>F$48,"",IF(OR(F$48="",F$48=0),"",IF(F$48=$C53,OFFSET($D$16,0,$C52)+OFFSET($D$13,0,$C52),OFFSET($D$16,0,$C52)))) -> 38763243 | G53: =IF($C53>G$48,"",IF(OR(G$48="",G$48=0),"",IF(G$48=$C53,OFFSET($D$16,0,$C52)+OFFSET($D$13,0,$C52),OFFSET($D$16,0,$C52)))) -> 2288952.2 | H53: =IF($C53>H$48,"",IF(OR(H$48="",H$48=0),"",IF(H$48=$C53,OFFSET($D$16,0,$C52)+OFFSET($D$13,0,$C52),OFFSET($D$16,0,$C52)))) -> 2288952.2 | I53: =IF($C53>I$48,"",IF(OR(I$48="",I$48=0),"",IF(I$48=$C53,OFFSET($D$16,0,$C52)+OFFSET($D$13,0,$C52),OFFSET($D$16,0,$C52)))) -> 2288952.2 | J53: =IF($C53>J$48,"",IF(OR(J$48="",J$48=0),"",IF(J$48=$C53,OFFSET($D$16,0,$C52)+OFFSET($D$13,0,$C52),OFFSET($D$16,0,$C52)))) -> 2288952.2 | K53: =IF($C53>K$48,"",IF(OR(K$48="",K$48=0),"",IF(K$48=$C53,OFFSET($D$16,0,$C52)+OFFSET($D$13,0,$C52),OFFSET($D$16,0,$C52)))) -> 2288952.2 | ... R53: =IF($C53>R$48,"",IF(OR(R$48="",R$48=0),"",IF(R$48=$C53,OFFSET($D$16,0,$C52)+OFFSET($D$13,0,$C52),OFFSET($D$16,0,$C52)))) -> 2288952.2
C54: =C53+1 -> 4 | D54: =IF($C54>D$48,"",IF(OR(D$48="",D$48=0),"",IF(D$48=$C54,OFFSET($D$16,0,$C53)+OFFSET($D$13,0,$C53),OFFSET($D$16,0,$C53)))) | E54: =IF($C54>E$48,"",IF(OR(E$48="",E$48=0),"",IF(E$48=$C54,OFFSET($D$16,0,$C53)+OFFSET($D$13,0,$C53),OFFSET($D$16,0,$C53)))) | F54: =IF($C54>F$48,"",IF(OR(F$48="",F$48=0),"",IF(F$48=$C54,OFFSET($D$16,0,$C53)+OFFSET($D$13,0,$C53),OFFSET($D$16,0,$C53)))) | G54: =IF($C54>G$48,"",IF(OR(G$48="",G$48=0),"",IF(G$48=$C54,OFFSET($D$16,0,$C53)+OFFSET($D$13,0,$C53),OFFSET($D$16,0,$C53)))) -> 38899957 | H54: =IF($C54>H$48,"",IF(OR(H$48="",H$48=0),"",IF(H$48=$C54,OFFSET($D$16,0,$C53)+OFFSET($D$13,0,$C53),OFFSET($D$16,0,$C53)))) -> 2311878.6 | I54: =IF($C54>I$48,"",IF(OR(I$48="",I$48=0),"",IF(I$48=$C54,OFFSET($D$16,0,$C53)+OFFSET($D$13,0,$C53),OFFSET($D$16,0,$C53)))) -> 2311878.6 | J54: =IF($C54>J$48,"",IF(OR(J$48="",J$48=0),"",IF(J$48=$C54,OFFSET($D$16,0,$C53)+OFFSET($D$13,0,$C53),OFFSET($D$16,0,$C53)))) -> 2311878.6 | K54: =IF($C54>K$48,"",IF(OR(K$48="",K$48=0),"",IF(K$48=$C54,OFFSET($D$16,0,$C53)+OFFSET($D$13,0,$C53),OFFSET($D$16,0,$C53)))) -> 2311878.6 | ... R54: =IF($C54>R$48,"",IF(OR(R$48="",R$48=0),"",IF(R$48=$C54,OFFSET($D$16,0,$C53)+OFFSET($D$13,0,$C53),OFFSET($D$16,0,$C53)))) -> 2311878.6
...

Sheet Investor Returns
B2: Property Level Returns
B4: Promote Structure Method | D4: IRR
B5: Return of Capital Method | D5: Pari Passu
B7: Equity Contributions | C7: % | D7: Amount | J7: Error Check: | K7: =IF(ROUND(K9,0)=ROUND(K8,0),"OK","Error") -> OK
B8: General Partner (GP) | C8: 0.1 | D8: =Equity_Share_Sponsor*Total_Equity -> 1966879.2 | E8: =Equity_Share_Sponsor=1 -> FALSE | J8: Profit Dist.: | K8: =(D27+D41)/1000000 -> 15.9096
B9: Limited Partner (LP) | C9: =1-C8 -> 0.9 | D9: =Equity_Share_LPs*Total_Equity -> 17701913 | J9: Net BTCF: | K9: =SUM(F48:U48)/1000000 -> 15.9096
B10: Total Equity | C10: =SUM(C8:C9) -> 1 | D10: =-SUMIF(F51:U51,"<0") -> 19668792
F12: Promote Structure Incentive Breakdown | H12: Distribution as %
B13: ="Promote Structure ("&$D$4&" Hurdles)" -> Promote Structure (IRR Hurdles) | H13: Sponsor % | I13: LP % | J13: Total Check | K13: Description
B14: Hurdle 1 (Preferred Return) | C14: Equity Multiple | D14: Pref | E14: =IF($D$4="EM",C15,D15) -> 0.08 | F14: Sponsor Promote | H14: =Equity_Share_Sponsor -> 0.1 | I14: =1-H14 -> 0.9 | J14: =SUM(H14:I14) -> 1 | K14: =IF(I14=Equity_Share_LPs,"Pref pro rata to LP/GP, then pro rata return of capital","Return of capital and pref NOT pro rata") -> Pref pro rata to LP/GP, then pro rata return of capital
B15: Hurdle 2 | C15: 1.15 | D15: 0.08 | E15: =IF($D$4="EM",C16,D16) -> 0.12 | F15: 0.1 | H15: =1-(Equity_Share_LPs*(1-F15)) -> 0.19 | I15: =1-H15 -> 0.81 | J15: =SUM(H15:I15) -> 1 | K15: =IF(Equity_Share_Sponsor<>H14,TEXT(I14,"0.00%")&"/"&TEXT(H14,"0.00%")&" to "&(IF(D4="IRR",TEXT(E14,"0.00%"),TEXT(E14,"0.00x")))&", then "&TEXT(I15,"0.00%")&"/"&TEXT(H15,"0.00%")&" to "&(IF(D4="IRR",TEXT(E15,"0.00%"),TEXT(E15,"0.00x"))),"Pro rata to LP/GP to "&(IF(D4="IRR",TEXT(E14,"0.00%"),TEXT(E14,"0.00x")))&", then "&TEXT(I15,"0.00%")&"/"&TEXT(H15,"0.00%")&" to "&(IF(D4="IRR",TEXT(E15,"0.00%"),TEXT(E15,"0.00x")))) -> Pro rata to LP/GP to 8.00%, then 81.00%/19.00% to 12.00%
B16: Hurdle 3 | C16: 1.3 | D16: 0.12 | E16: =IF($D$4="EM",C17,D17) -> 0.15 | F16: 0.12 | H16: =1-(Equity_Share_LPs*(1-F16)) -> 0.208 | I16: =1-H16 -> 0.792 | J16: =SUM(H16:I16) -> 1 | K16: =TEXT(I15,"0.00%")&"/"&TEXT(H15,"0.00%")&" to "&(IF(D4="IRR",TEXT(E15,"0.00%"),TEXT(E15,"0.00x")))&", then "&TEXT(I16,"0.00%")&"/"&TEXT(H16,"0.00%")&" to "&(IF(D4="IRR",TEXT(E16,"0.00%"),TEXT(E16,"0.00x"))) -> 81.00%/19.00% to 12.00%, then 79.20%/20.80% to 15.00%
B17: Hurdle 4 | C17: 1.45 | D17: 0.15 | F17: 0.15 | H17: =1-(Equity_Share_LPs*(1-F17)) -> 0.235 | I17: =1-H17 -> 0.765 | J17: =SUM(H17:I17) -> 1 | K17: =TEXT(I16,"0.00%")&"/"&TEXT(H16,"0.00%")&" to "&(IF(D4="IRR",TEXT(E16,"0.00%"),TEXT(E16,"0.00x")))&", then "&TEXT(I17,"0.00%")&"/"&TEXT(H17,"0.00%")&" thereafter" -> 79.20%/20.80% to 15.00%, then 76.50%/23.50% thereafter
B19: Summary of Partnership Level Returns | F19: 0 | G19: =IF(OR(F$19="",F$19=Effective_Hold_Period),"",F$19+1) -> 1 | H19: =IF(OR(G$19="",G$19=Effective_Hold_Period),"",G$19+1) -> 2 | I19: =IF(OR(H$19="",H$19=Effective_Hold_Period),"",H$19+1) -> 3 | J19: =IF(OR(I$19="",I$19=Effective_Hold_Period),"",I$19+1) -> 4 | K19: =IF(OR(J$19="",J$19=Effective_Hold_Period),"",J$19+1) -> 5 | L19: =IF(OR(K$19="",K$19=Effective_Hold_Period),"",K$19+1) -> 6 | M19: =IF(OR(L$19="",L$19=Effective_Hold_Period),"",L$19+1) -> 7 | N19: =IF(OR(M$19="",M$19=Effective_Hold_Period),"",M$19+1) -> 8 | ... U19: =IF(OR(T$19="",T$19=Effective_Hold_Period),"",T$19+1) -> 15
B20: Limited Partner (LP) Returns | C20: Error Check
B21: Preferred Return | C21: =IF(ROUND(D21,0)=ROUND(SUM(F21:U21),0),"OK","ERROR") -> OK | D21: =(Promote_Method="IRR")*(SUM($F$78:$U$78)-D22)+(Promote_Method="EM")*(SUM($F$78:$U$78)-D22) -> -2953070.6 | F21: =IF(F$19="","",0) -> 0 | G21: =IF(G$19="","",MIN($D21-SUM($F$21:F$21),G$25)) -> -2953070.6 | H21: =IF(H$19="","",MIN($D21-SUM($F$21:G$21),H$25)) -> 0 | I21: =IF(I$19="","",MIN($D21-SUM($F$21:H$21),I$25)) -> 0 | J21: =IF(J$19="","",MIN($D21-SUM($F$21:I$21),J$25)) -> 0 | K21: =IF(K$19="","",MIN($D21-SUM($F$21:J$21),K$25)) -> 0 | L21: =IF(L$19="","",MIN($D21-SUM($F$21:K$21),L$25)) -> 0 | M21: =IF(M$19="","",MIN($D21-SUM($F$21:L$21),M$25)) -> 0 | N21: =IF(N$19="","",MIN($D21-SUM($F$21:M$21),N$25)) -> 0 | ... U21: =IF(U$19="","",MIN($D21-SUM($F$21:T$21),U$25)) -> 0
B22: Return of Capital | C22: =IF(ROUND(D22,0)=ROUND(SUM(F22:U22),0),"OK","ERROR") -> OK | D22: =MIN(D25,D26) -> 17701913 | F22: =IF(F$19="","",0) -> 0 | G22: =IF(G$19="","",MIN($D22-SUM($F$22:F$22),G$25-G$21)) -> 3403760.4 | H22: =IF(H$19="","",MIN($D22-SUM($F$22:G$22),H$25-H$21)) -> 612419.34 | I22: =IF(I$19="","",MIN($D22-SUM($F$22:H$22),I$25-I$21)) -> 843364.09 | J22: =IF(J$19="","",MIN($D22-SUM($F$22:I$22),J$25-J$21)) -> 863997.86 | K22: =IF(K$19="","",MIN($D22-SUM($F$22:J$22),K$25-K$21)) -> 884640.75 | L22: =IF(L$19="","",MIN($D22-SUM($F$22:K$22),L$25-L$21)) -> 905284.02 | M22: =IF(M$19="","",MIN($D22-SUM($F$22:L$22),M$25-M$21)) -> 925918.57 | N22: =IF(N$19="","",MIN($D22-SUM($F$22:M$22),N$25-N$21)) -> 946534.88 | ... U22: =IF(U$19="","",MIN($D22-SUM($F$22:T$22),U$25-U$21)) -> 2206171.8
